Workbook

Sheet Dashboard
A1: Bridg Competitive Benchmark
A2: 100 USDC → USDC · 6 routes · quotes read from each site's own web UI, no wallet connected · collected 2026-09-23 14:18 – 14:30 UTC
A4: Headline
A5: Routes where Bridg's best beat every direct quote | B5: =COUNTIF('Competitor Matrix'!$E$28:$E$33,">=-2")&" / 6"
A6: Venue pairs where Bridg's listing matches the venue's site | B6: =COUNTIF('Venue Analysis'!$Z$5:$Z$74,"Match*")&" / "&COUNTA('Venue Analysis'!$Z$5:$Z$74)
A7: … Bridg lists LESS than the venue's own site | B7: =COUNTIF('Venue Analysis'!$Z$5:$Z$74,"Bridg LOWER*")
A8: … Bridg lists MORE than the venue's own site | B8: =COUNTIF('Venue Analysis'!$Z$5:$Z$74,"Bridg HIGHER*")
A9: … venue quotes on its site but is missing from Bridg | B9: =COUNTIF('Venue Analysis'!$Z$5:$Z$74,"NOT LISTED*")
A10: Worst venue-accuracy gap (bps, ex-Bridg fee) | B10: =MIN('Venue Analysis'!$X$5:$X$74)
A11: Campaign (all quotes collected in one window) | B11: 20260923T141817Z · 2026-09-23 14:18:34 – 14:30:59 UTC
A12: Worst value-read spread within a run (s) | B12: =MAX('Raw Quotes'!$S:$S)
A13: Venues / platforms compared | B13: 13 venues + 1 platforms
A14: Blocked (no public quote) | B14: 3 venues + 4 platforms
A17: Route winners (Bridg best vs best direct quote)
A18: Route | B18: Bridg best | C18: Best elsewhere | D18: Site | E18: Bridg vs best (bps) | F18: Sites Bridg beats | G18: Sites beating Bridg
A19: ='Competitor Matrix'!A28 | B19: ='Competitor Matrix'!B28 | C19: ='Competitor Matrix'!C28 | D19: ='Competitor Matrix'!D28 | E19: ='Competitor Matrix'!E28 | F19: ='Competitor Matrix'!F28 | G19: ='Competitor Matrix'!G28
A20: ='Competitor Matrix'!A29 | B20: ='Competitor Matrix'!B29 | C20: ='Competitor Matrix'!C29 | D20: ='Competitor Matrix'!D29 | E20: ='Competitor Matrix'!E29 | F20: ='Competitor Matrix'!F29 | G20: ='Competitor Matrix'!G29
A21: ='Competitor Matrix'!A30 | B21: ='Competitor Matrix'!B30 | C21: ='Competitor Matrix'!C30 | D21: ='Competitor Matrix'!D30 | E21: ='Competitor Matrix'!E30 | F21: ='Competitor Matrix'!F30 | G21: ='Competitor Matrix'!G30
A22: ='Competitor Matrix'!A31 | B22: ='Competitor Matrix'!B31 | C22: ='Competitor Matrix'!C31 | D22: ='Competitor Matrix'!D31 | E22: ='Competitor Matrix'!E31 | F22: ='Competitor Matrix'!F31 | G22: ='Competitor Matrix'!G31
A23: ='Competitor Matrix'!A32 | B23: ='Competitor Matrix'!B32 | C23: ='Competitor Matrix'!C32 | D23: ='Competitor Matrix'!D32 | E23: ='Competitor Matrix'!E32 | F23: ='Competitor Matrix'!F32 | G23: ='Competitor Matrix'!G32
A24: ='Competitor Matrix'!A33 | B24: ='Competitor Matrix'!B33 | C24: ='Competitor Matrix'!C33 | D24: ='Competitor Matrix'!D33 | E24: ='Competitor Matrix'!E33 | F24: ='Competitor Matrix'!F33 | G24: ='Competitor Matrix'!G33
A26: Venue accuracy (avg gap ex-Bridg fee, bps) — Bridg listed vs venue's own site
A27: Venue | B27: SOL → ETH | C27: ETH → SOL | D27: SOL → BSC | E27: BSC → SOL | F27: SOL → Base | G27: Base → SOL
A28: Relay | B28: =IF('Venue Analysis'!T5=0,"not listed",'Venue Analysis'!X5) | C28: =IF('Venue Analysis'!T18=0,"not listed",'Venue Analysis'!X18) | D28: =IF('Venue Analysis'!T31=0,"not listed",'Venue Analysis'!X31) | E28: =IF('Venue Analysis'!T40=0,"not listed",'Venue Analysis'!X40) | F28: =IF('Venue Analysis'!T50=0,"not listed",'Venue Analysis'!X50) | G28: =IF('Venue Analysis'!T62=0,"not listed",'Venue Analysis'!X62)
A29: deBridge | B29: =IF('Venue Analysis'!T6=0,"not listed",'Venue Analysis'!X6) | C29: =IF('Venue Analysis'!T19=0,"not listed",'Venue Analysis'!X19) | D29: =IF('Venue Analysis'!T32=0,"not listed",'Venue Analysis'!X32) | E29: =IF('Venue Analysis'!T41=0,"not listed",'Venue Analysis'!X41) | F29: =IF('Venue Analysis'!T51=0,"not listed",'Venue Analysis'!X51) | G29: =IF('Venue Analysis'!T63=0,"not listed",'Venue Analysis'!X63)
A30: LI.FI (Jumper) | B30: =IF('Venue Analysis'!T7=0,"not listed",'Venue Analysis'!X7) | C30: =IF('Venue Analysis'!T20=0,"not listed",'Venue Analysis'!X20) | D30: =IF('Venue Analysis'!T33=0,"not listed",'Venue Analysis'!X33) | E30: =IF('Venue Analysis'!T42=0,"not listed",'Venue Analysis'!X42) | F30: =IF('Venue Analysis'!T52=0,"not listed",'Venue Analysis'!X52) | G30: =IF('Venue Analysis'!T64=0,"not listed",'Venue Analysis'!X64)
A31: Across | B31: =IF('Venue Analysis'!T8=0,"not listed",'Venue Analysis'!X8) | C31: =IF('Venue Analysis'!T21=0,"not listed",'Venue Analysis'!X21) | D31: =IF('Venue Analysis'!T34=0,"not listed",'Venue Analysis'!X34) | E31: =IF('Venue Analysis'!T43=0,"not listed",'Venue Analysis'!X43) | F31: =IF('Venue Analysis'!T53=0,"not listed",'Venue Analysis'!X53) | G31: =IF('Venue Analysis'!T65=0,"not listed",'Venue Analysis'!X65)
A32: Mayan | B32: =IF('Venue Analysis'!T9=0,"not listed",'Venue Analysis'!X9) | C32: =IF('Venue Analysis'!T22=0,"not listed",'Venue Analysis'!X22) | D32: =IF('Venue Analysis'!T35=0,"not listed",'Venue Analysis'!X35) | E32: =IF('Venue Analysis'!T44=0,"not listed",'Venue Analysis'!X44) | F32: =IF('Venue Analysis'!T54=0,"not listed",'Venue Analysis'!X54) | G32: =IF('Venue Analysis'!T66=0,"not listed",'Venue Analysis'!X66)
A33: Allbridge Core | B33: =IF('Venue Analysis'!T10=0,"not listed",'Venue Analysis'!X10) | C33: =IF('Venue Analysis'!T23=0,"not listed",'Venue Analysis'!X23) | D33: n/a | E33: n/a | F33: =IF('Venue Analysis'!T55=0,"not listed",'Venue Analysis'!X55) | G33: =IF('Venue Analysis'!T67=0,"not listed",'Venue Analysis'!X67)
A34: CCTP (via Portal) | B34: =IF('Venue Analysis'!T11=0,"not listed",'Venue Analysis'!X11) | C34: =IF('Venue Analysis'!T24=0,"not listed",'Venue Analysis'!X24) | D34: n/a | E34: n/a | F34: =IF('Venue Analysis'!T56=0,"not listed",'Venue Analysis'!X56) | G34: =IF('Venue Analysis'!T68=0,"not listed",'Venue Analysis'!X68)
A35: Husher | B35: =IF('Venue Analysis'!T12=0,"not listed",'Venue Analysis'!X12) | C35: =IF('Venue Analysis'!T25=0,"not listed",'Venue Analysis'!X25) | D35: =IF('Venue Analysis'!T36=0,"not listed",'Venue Analysis'!X36) | E35: =IF('Venue Analysis'!T45=0,"not listed",'Venue Analysis'!X45) | F35: =IF('Venue Analysis'!T57=0,"not listed",'Venue Analysis'!X57) | G35: =IF('Venue Analysis'!T69=0,"not listed",'Venue Analysis'!X69)
A36: Layerswap | B36: =IF('Venue Analysis'!T13=0,"not listed",'Venue Analysis'!X13) | C36: =IF('Venue Analysis'!T26=0,"not listed",'Venue Analysis'!X26) | D36: =IF('Venue Analysis'!T37=0,"not listed",'Venue Analysis'!X37) | E36: =IF('Venue Analysis'!T46=0,"not listed",'Venue Analysis'!X46) | F36: =IF('Venue Analysis'!T58=0,"not listed",'Venue Analysis'!X58) | G36: =IF('Venue Analysis'!T70=0,"not listed",'Venue Analysis'!X70)
A37: Meson | B37: =IF('Venue Analysis'!T14=0,"not listed",'Venue Analysis'!X14) | C37: =IF('Venue Analysis'!T27=0,"not listed",'Venue Analysis'!X27) | D37: =IF('Venue Analysis'!T38=0,"not listed",'Venue Analysis'!X38) | E37: =IF('Venue Analysis'!T47=0,"not listed",'Venue Analysis'!X47) | F37: =IF('Venue Analysis'!T59=0,"not listed",'Venue Analysis'!X59) | G37: =IF('Venue Analysis'!T71=0,"not listed",'Venue Analysis'!X71)
A38: SimpleSwap | B38: =IF('Venue Analysis'!T15=0,"not listed",'Venue Analysis'!X15) | C38: =IF('Venue Analysis'!T28=0,"not listed",'Venue Analysis'!X28) | D38: =IF('Venue Analysis'!T39=0,"not listed",'Venue Analysis'!X39) | E38: =IF('Venue Analysis'!T48=0,"not listed",'Venue Analysis'!X48) | F38: =IF('Venue Analysis'!T60=0,"not listed",'Venue Analysis'!X60) | G38: =IF('Venue Analysis'!T72=0,"not listed",'Venue Analysis'!X72)
A39: Skip Go | B39: =IF('Venue Analysis'!T16=0,"not listed",'Venue Analysis'!X16) | C39: =IF('Venue Analysis'!T29=0,"not listed",'Venue Analysis'!X29) | D39: n/a | E39: n/a | F39: =IF('Venue Analysis'!T61=0,"not listed",'Venue Analysis'!X61) | G39: =IF('Venue Analysis'!T73=0,"not listed",'Venue Analysis'!X73)
A40: Symbiosis | B40: =IF('Venue Analysis'!T17=0,"not listed",'Venue Analysis'!X17) | C40: =IF('Venue Analysis'!T30=0,"not listed",'Venue Analysis'!X30) | D40: n/a | E40: =IF('Venue Analysis'!T49=0,"not listed",'Venue Analysis'!X49) | F40: n/a | G40: =IF('Venue Analysis'!T74=0,"not listed",'Venue Analysis'!X74)
A42: Green = linked from other sheets. Red cells: Bridg lower / going direct pays more; blue: Bridg higher / Bridg pays more. Hypotheses in Issues are unverified.
A44: Run timing — every site typed at one instant, then all read their compared value at one instant
A45: Route | B45: Sample | C45: Typed at (UTC) | D45: Values read at (UTC) | E45: Typed spread (s) | F45: Read spread (s) | G45: Screenshot spread (s) | H45: Sites OK
A46: SOL → ETH | B46: 1 | C46: 2026-09-23T14:18:34.538Z | D46: 2026-09-23T14:18:55.406Z | E46: 0.187 | F46: 0.006 | G46: 0.183 | H46: 15/15
...

Sheet Competitor Matrix
A1: Competitor Matrix — does a user get more on Bridg, or by going direct?
A2: Savings (bps) = (Bridg best − other) / 100 × 10,000. Positive = Bridg pays more. Bridg best = what Bridg's own page says you receive on its best-price route. Source-chain gas paid separately is not counted on either side.
A4: Average savings (bps) by site and route
A5: Site | B5: Kind | C5: SOL → ETH | D5: ETH → SOL | E5: SOL → BSC | F5: BSC → SOL | G5: SOL → Base | H5: Base → SOL | N5: Avg other out (helper) | O5: SOL → ETH | P5: ETH → SOL | Q5: SOL → BSC | R5: BSC → SOL | S5: SOL → Base | T5: Base → SOL
A6: OpenSea | B6: platform | C6: =IFERROR(AVERAGEIFS($H$37:$H$256,$A$37:$A$256,"SOL → ETH",$C$37:$C$256,$A6),"n/a") | D6: =IFERROR(AVERAGEIFS($H$37:$H$256,$A$37:$A$256,"ETH → SOL",$C$37:$C$256,$A6),"n/a") | E6: =IFERROR(AVERAGEIFS($H$37:$H$256,$A$37:$A$256,"SOL → BSC",$C$37:$C$256,$A6),"n/a") | F6: =IFERROR(AVERAGEIFS($H$37:$H$256,$A$37:$A$256,"BSC → SOL",$C$37:$C$256,$A6),"n/a") | G6: =IFERROR(AVERAGEIFS($H$37:$H$256,$A$37:$A$256,"SOL → Base",$C$37:$C$256,$A6),"n/a") | H6: =IFERROR(AVERAGEIFS($H$37:$H$256,$A$37:$A$256,"Base → SOL",$C$37:$C$256,$A6),"n/a") | N6: OpenSea | O6: =IFERROR(AVERAGEIFS($G$37:$G$256,$A$37:$A$256,"SOL → ETH",$C$37:$C$256,$N6),"") | P6: =IFERROR(AVERAGEIFS($G$37:$G$256,$A$37:$A$256,"ETH → SOL",$C$37:$C$256,$N6),"") | Q6: =IFERROR(AVERAGEIFS($G$37:$G$256,$A$37:$A$256,"SOL → BSC",$C$37:$C$256,$N6),"") | R6: =IFERROR(AVERAGEIFS($G$37:$G$256,$A$37:$A$256,"BSC → SOL",$C$37:$C$256,$N6),"") | S6: =IFERROR(AVERAGEIFS($G$37:$G$256,$A$37:$A$256,"SOL → Base",$C$37:$C$256,$N6),"") | T6: =IFERROR(AVERAGEIFS($G$37:$G$256,$A$37:$A$256,"Base → SOL",$C$37:$C$256,$N6),"")
A7: Relay | B7: venue | C7: =IFERROR(AVERAGEIFS($H$37:$H$256,$A$37:$A$256,"SOL → ETH",$C$37:$C$256,$A7),"n/a") | D7: =IFERROR(AVERAGEIFS($H$37:$H$256,$A$37:$A$256,"ETH → SOL",$C$37:$C$256,$A7),"n/a") | E7: =IFERROR(AVERAGEIFS($H$37:$H$256,$A$37:$A$256,"SOL → BSC",$C$37:$C$256,$A7),"n/a") | F7: =IFERROR(AVERAGEIFS($H$37:$H$256,$A$37:$A$256,"BSC → SOL",$C$37:$C$256,$A7),"n/a") | G7: =IFERROR(AVERAGEIFS($H$37:$H$256,$A$37:$A$256,"SOL → Base",$C$37:$C$256,$A7),"n/a") | H7: =IFERROR(AVERAGEIFS($H$37:$H$256,$A$37:$A$256,"Base → SOL",$C$37:$C$256,$A7),"n/a") | N7: Relay | O7: =IFERROR(AVERAGEIFS($G$37:$G$256,$A$37:$A$256,"SOL → ETH",$C$37:$C$256,$N7),"") | P7: =IFERROR(AVERAGEIFS($G$37:$G$256,$A$37:$A$256,"ETH → SOL",$C$37:$C$256,$N7),"") | Q7: =IFERROR(AVERAGEIFS($G$37:$G$256,$A$37:$A$256,"SOL → BSC",$C$37:$C$256,$N7),"") | R7: =IFERROR(AVERAGEIFS($G$37:$G$256,$A$37:$A$256,"BSC → SOL",$C$37:$C$256,$N7),"") | S7: =IFERROR(AVERAGEIFS($G$37:$G$256,$A$37:$A$256,"SOL → Base",$C$37:$C$256,$N7),"") | T7: =IFERROR(AVERAGEIFS($G$37:$G$256,$A$37:$A$256,"Base → SOL",$C$37:$C$256,$N7),"")
A8: deBridge | B8: venue | C8: =IFERROR(AVERAGEIFS($H$37:$H$256,$A$37:$A$256,"SOL → ETH",$C$37:$C$256,$A8),"n/a") | D8: =IFERROR(AVERAGEIFS($H$37:$H$256,$A$37:$A$256,"ETH → SOL",$C$37:$C$256,$A8),"n/a") | E8: =IFERROR(AVERAGEIFS($H$37:$H$256,$A$37:$A$256,"SOL → BSC",$C$37:$C$256,$A8),"n/a") | F8: =IFERROR(AVERAGEIFS($H$37:$H$256,$A$37:$A$256,"BSC → SOL",$C$37:$C$256,$A8),"n/a") | G8: =IFERROR(AVERAGEIFS($H$37:$H$256,$A$37:$A$256,"SOL → Base",$C$37:$C$256,$A8),"n/a") | H8: =IFERROR(AVERAGEIFS($H$37:$H$256,$A$37:$A$256,"Base → SOL",$C$37:$C$256,$A8),"n/a") | N8: deBridge | O8: =IFERROR(AVERAGEIFS($G$37:$G$256,$A$37:$A$256,"SOL → ETH",$C$37:$C$256,$N8),"") | P8: =IFERROR(AVERAGEIFS($G$37:$G$256,$A$37:$A$256,"ETH → SOL",$C$37:$C$256,$N8),"") | Q8: =IFERROR(AVERAGEIFS($G$37:$G$256,$A$37:$A$256,"SOL → BSC",$C$37:$C$256,$N8),"") | R8: =IFERROR(AVERAGEIFS($G$37:$G$256,$A$37:$A$256,"BSC → SOL",$C$37:$C$256,$N8),"") | S8: =IFERROR(AVERAGEIFS($G$37:$G$256,$A$37:$A$256,"SOL → Base",$C$37:$C$256,$N8),"") | T8: =IFERROR(AVERAGEIFS($G$37:$G$256,$A$37:$A$256,"Base → SOL",$C$37:$C$256,$N8),"")
A9: LI.FI (Jumper) | B9: venue | C9: =IFERROR(AVERAGEIFS($H$37:$H$256,$A$37:$A$256,"SOL → ETH",$C$37:$C$256,$A9),"n/a") | D9: =IFERROR(AVERAGEIFS($H$37:$H$256,$A$37:$A$256,"ETH → SOL",$C$37:$C$256,$A9),"n/a") | E9: =IFERROR(AVERAGEIFS($H$37:$H$256,$A$37:$A$256,"SOL → BSC",$C$37:$C$256,$A9),"n/a") | F9: =IFERROR(AVERAGEIFS($H$37:$H$256,$A$37:$A$256,"BSC → SOL",$C$37:$C$256,$A9),"n/a") | G9: =IFERROR(AVERAGEIFS($H$37:$H$256,$A$37:$A$256,"SOL → Base",$C$37:$C$256,$A9),"n/a") | H9: =IFERROR(AVERAGEIFS($H$37:$H$256,$A$37:$A$256,"Base → SOL",$C$37:$C$256,$A9),"n/a") | N9: LI.FI (Jumper) | O9: =IFERROR(AVERAGEIFS($G$37:$G$256,$A$37:$A$256,"SOL → ETH",$C$37:$C$256,$N9),"") | P9: =IFERROR(AVERAGEIFS($G$37:$G$256,$A$37:$A$256,"ETH → SOL",$C$37:$C$256,$N9),"") | Q9: =IFERROR(AVERAGEIFS($G$37:$G$256,$A$37:$A$256,"SOL → BSC",$C$37:$C$256,$N9),"") | R9: =IFERROR(AVERAGEIFS($G$37:$G$256,$A$37:$A$256,"BSC → SOL",$C$37:$C$256,$N9),"") | S9: =IFERROR(AVERAGEIFS($G$37:$G$256,$A$37:$A$256,"SOL → Base",$C$37:$C$256,$N9),"") | T9: =IFERROR(AVERAGEIFS($G$37:$G$256,$A$37:$A$256,"Base → SOL",$C$37:$C$256,$N9),"")
A10: Across | B10: venue | C10: =IFERROR(AVERAGEIFS($H$37:$H$256,$A$37:$A$256,"SOL → ETH",$C$37:$C$256,$A10),"n/a") | D10: =IFERROR(AVERAGEIFS($H$37:$H$256,$A$37:$A$256,"ETH → SOL",$C$37:$C$256,$A10),"n/a") | E10: =IFERROR(AVERAGEIFS($H$37:$H$256,$A$37:$A$256,"SOL → BSC",$C$37:$C$256,$A10),"n/a") | F10: =IFERROR(AVERAGEIFS($H$37:$H$256,$A$37:$A$256,"BSC → SOL",$C$37:$C$256,$A10),"n/a") | G10: =IFERROR(AVERAGEIFS($H$37:$H$256,$A$37:$A$256,"SOL → Base",$C$37:$C$256,$A10),"n/a") | H10: =IFERROR(AVERAGEIFS($H$37:$H$256,$A$37:$A$256,"Base → SOL",$C$37:$C$256,$A10),"n/a") | N10: Across | O10: =IFERROR(AVERAGEIFS($G$37:$G$256,$A$37:$A$256,"SOL → ETH",$C$37:$C$256,$N10),"") | P10: =IFERROR(AVERAGEIFS($G$37:$G$256,$A$37:$A$256,"ETH → SOL",$C$37:$C$256,$N10),"") | Q10: =IFERROR(AVERAGEIFS($G$37:$G$256,$A$37:$A$256,"SOL → BSC",$C$37:$C$256,$N10),"") | R10: =IFERROR(AVERAGEIFS($G$37:$G$256,$A$37:$A$256,"BSC → SOL",$C$37:$C$256,$N10),"") | S10: =IFERROR(AVERAGEIFS($G$37:$G$256,$A$37:$A$256,"SOL → Base",$C$37:$C$256,$N10),"") | T10: =IFERROR(AVERAGEIFS($G$37:$G$256,$A$37:$A$256,"Base → SOL",$C$37:$C$256,$N10),"")
A11: Mayan | B11: venue | C11: =IFERROR(AVERAGEIFS($H$37:$H$256,$A$37:$A$256,"SOL → ETH",$C$37:$C$256,$A11),"n/a") | D11: =IFERROR(AVERAGEIFS($H$37:$H$256,$A$37:$A$256,"ETH → SOL",$C$37:$C$256,$A11),"n/a") | E11: =IFERROR(AVERAGEIFS($H$37:$H$256,$A$37:$A$256,"SOL → BSC",$C$37:$C$256,$A11),"n/a") | F11: =IFERROR(AVERAGEIFS($H$37:$H$256,$A$37:$A$256,"BSC → SOL",$C$37:$C$256,$A11),"n/a") | G11: =IFERROR(AVERAGEIFS($H$37:$H$256,$A$37:$A$256,"SOL → Base",$C$37:$C$256,$A11),"n/a") | H11: =IFERROR(AVERAGEIFS($H$37:$H$256,$A$37:$A$256,"Base → SOL",$C$37:$C$256,$A11),"n/a") | N11: Mayan | O11: =IFERROR(AVERAGEIFS($G$37:$G$256,$A$37:$A$256,"SOL → ETH",$C$37:$C$256,$N11),"") | P11: =IFERROR(AVERAGEIFS($G$37:$G$256,$A$37:$A$256,"ETH → SOL",$C$37:$C$256,$N11),"") | Q11: =IFERROR(AVERAGEIFS($G$37:$G$256,$A$37:$A$256,"SOL → BSC",$C$37:$C$256,$N11),"") | R11: =IFERROR(AVERAGEIFS($G$37:$G$256,$A$37:$A$256,"BSC → SOL",$C$37:$C$256,$N11),"") | S11: =IFERROR(AVERAGEIFS($G$37:$G$256,$A$37:$A$256,"SOL → Base",$C$37:$C$256,$N11),"") | T11: =IFERROR(AVERAGEIFS($G$37:$G$256,$A$37:$A$256,"Base → SOL",$C$37:$C$256,$N11),"")
A12: Allbridge Core | B12: venue | C12: =IFERROR(AVERAGEIFS($H$37:$H$256,$A$37:$A$256,"SOL → ETH",$C$37:$C$256,$A12),"n/a") | D12: =IFERROR(AVERAGEIFS($H$37:$H$256,$A$37:$A$256,"ETH → SOL",$C$37:$C$256,$A12),"n/a") | E12: =IFERROR(AVERAGEIFS($H$37:$H$256,$A$37:$A$256,"SOL → BSC",$C$37:$C$256,$A12),"n/a") | F12: =IFERROR(AVERAGEIFS($H$37:$H$256,$A$37:$A$256,"BSC → SOL",$C$37:$C$256,$A12),"n/a") | G12: =IFERROR(AVERAGEIFS($H$37:$H$256,$A$37:$A$256,"SOL → Base",$C$37:$C$256,$A12),"n/a") | H12: =IFERROR(AVERAGEIFS($H$37:$H$256,$A$37:$A$256,"Base → SOL",$C$37:$C$256,$A12),"n/a") | N12: Allbridge Core | O12: =IFERROR(AVERAGEIFS($G$37:$G$256,$A$37:$A$256,"SOL → ETH",$C$37:$C$256,$N12),"") | P12: =IFERROR(AVERAGEIFS($G$37:$G$256,$A$37:$A$256,"ETH → SOL",$C$37:$C$256,$N12),"") | Q12: =IFERROR(AVERAGEIFS($G$37:$G$256,$A$37:$A$256,"SOL → BSC",$C$37:$C$256,$N12),"") | R12: =IFERROR(AVERAGEIFS($G$37:$G$256,$A$37:$A$256,"BSC → SOL",$C$37:$C$256,$N12),"") | S12: =IFERROR(AVERAGEIFS($G$37:$G$256,$A$37:$A$256,"SOL → Base",$C$37:$C$256,$N12),"") | T12: =IFERROR(AVERAGEIFS($G$37:$G$256,$A$37:$A$256,"Base → SOL",$C$37:$C$256,$N12),"")
A13: CCTP (via Portal) | B13: venue | C13: =IFERROR(AVERAGEIFS($H$37:$H$256,$A$37:$A$256,"SOL → ETH",$C$37:$C$256,$A13),"n/a") | D13: =IFERROR(AVERAGEIFS($H$37:$H$256,$A$37:$A$256,"ETH → SOL",$C$37:$C$256,$A13),"n/a") | E13: =IFERROR(AVERAGEIFS($H$37:$H$256,$A$37:$A$256,"SOL → BSC",$C$37:$C$256,$A13),"n/a") | F13: =IFERROR(AVERAGEIFS($H$37:$H$256,$A$37:$A$256,"BSC → SOL",$C$37:$C$256,$A13),"n/a") | G13: =IFERROR(AVERAGEIFS($H$37:$H$256,$A$37:$A$256,"SOL → Base",$C$37:$C$256,$A13),"n/a") | H13: =IFERROR(AVERAGEIFS($H$37:$H$256,$A$37:$A$256,"Base → SOL",$C$37:$C$256,$A13),"n/a") | N13: CCTP (via Portal) | O13: =IFERROR(AVERAGEIFS($G$37:$G$256,$A$37:$A$256,"SOL → ETH",$C$37:$C$256,$N13),"") | P13: =IFERROR(AVERAGEIFS($G$37:$G$256,$A$37:$A$256,"ETH → SOL",$C$37:$C$256,$N13),"") | Q13: =IFERROR(AVERAGEIFS($G$37:$G$256,$A$37:$A$256,"SOL → BSC",$C$37:$C$256,$N13),"") | R13: =IFERROR(AVERAGEIFS($G$37:$G$256,$A$37:$A$256,"BSC → SOL",$C$37:$C$256,$N13),"") | S13: =IFERROR(AVERAGEIFS($G$37:$G$256,$A$37:$A$256,"SOL → Base",$C$37:$C$256,$N13),"") | T13: =IFERROR(AVERAGEIFS($G$37:$G$256,$A$37:$A$256,"Base → SOL",$C$37:$C$256,$N13),"")
A14: Husher | B14: venue | C14: =IFERROR(AVERAGEIFS($H$37:$H$256,$A$37:$A$256,"SOL → ETH",$C$37:$C$256,$A14),"n/a") | D14: =IFERROR(AVERAGEIFS($H$37:$H$256,$A$37:$A$256,"ETH → SOL",$C$37:$C$256,$A14),"n/a") | E14: =IFERROR(AVERAGEIFS($H$37:$H$256,$A$37:$A$256,"SOL → BSC",$C$37:$C$256,$A14),"n/a") | F14: =IFERROR(AVERAGEIFS($H$37:$H$256,$A$37:$A$256,"BSC → SOL",$C$37:$C$256,$A14),"n/a") | G14: =IFERROR(AVERAGEIFS($H$37:$H$256,$A$37:$A$256,"SOL → Base",$C$37:$C$256,$A14),"n/a") | H14: =IFERROR(AVERAGEIFS($H$37:$H$256,$A$37:$A$256,"Base → SOL",$C$37:$C$256,$A14),"n/a") | N14: Husher | O14: =IFERROR(AVERAGEIFS($G$37:$G$256,$A$37:$A$256,"SOL → ETH",$C$37:$C$256,$N14),"") | P14: =IFERROR(AVERAGEIFS($G$37:$G$256,$A$37:$A$256,"ETH → SOL",$C$37:$C$256,$N14),"") | Q14: =IFERROR(AVERAGEIFS($G$37:$G$256,$A$37:$A$256,"SOL → BSC",$C$37:$C$256,$N14),"") | R14: =IFERROR(AVERAGEIFS($G$37:$G$256,$A$37:$A$256,"BSC → SOL",$C$37:$C$256,$N14),"") | S14: =IFERROR(AVERAGEIFS($G$37:$G$256,$A$37:$A$256,"SOL → Base",$C$37:$C$256,$N14),"") | T14: =IFERROR(AVERAGEIFS($G$37:$G$256,$A$37:$A$256,"Base → SOL",$C$37:$C$256,$N14),"")
A15: Layerswap | B15: venue | C15: =IFERROR(AVERAGEIFS($H$37:$H$256,$A$37:$A$256,"SOL → ETH",$C$37:$C$256,$A15),"n/a") | D15: =IFERROR(AVERAGEIFS($H$37:$H$256,$A$37:$A$256,"ETH → SOL",$C$37:$C$256,$A15),"n/a") | E15: =IFERROR(AVERAGEIFS($H$37:$H$256,$A$37:$A$256,"SOL → BSC",$C$37:$C$256,$A15),"n/a") | F15: =IFERROR(AVERAGEIFS($H$37:$H$256,$A$37:$A$256,"BSC → SOL",$C$37:$C$256,$A15),"n/a") | G15: =IFERROR(AVERAGEIFS($H$37:$H$256,$A$37:$A$256,"SOL → Base",$C$37:$C$256,$A15),"n/a") | H15: =IFERROR(AVERAGEIFS($H$37:$H$256,$A$37:$A$256,"Base → SOL",$C$37:$C$256,$A15),"n/a") | N15: Layerswap | O15: =IFERROR(AVERAGEIFS($G$37:$G$256,$A$37:$A$256,"SOL → ETH",$C$37:$C$256,$N15),"") | P15: =IFERROR(AVERAGEIFS($G$37:$G$256,$A$37:$A$256,"ETH → SOL",$C$37:$C$256,$N15),"") | Q15: =IFERROR(AVERAGEIFS($G$37:$G$256,$A$37:$A$256,"SOL → BSC",$C$37:$C$256,$N15),"") | R15: =IFERROR(AVERAGEIFS($G$37:$G$256,$A$37:$A$256,"BSC → SOL",$C$37:$C$256,$N15),"") | S15: =IFERROR(AVERAGEIFS($G$37:$G$256,$A$37:$A$256,"SOL → Base",$C$37:$C$256,$N15),"") | T15: =IFERROR(AVERAGEIFS($G$37:$G$256,$A$37:$A$256,"Base → SOL",$C$37:$C$256,$N15),"")
A16: Meson | B16: venue | C16: =IFERROR(AVERAGEIFS($H$37:$H$256,$A$37:$A$256,"SOL → ETH",$C$37:$C$256,$A16),"n/a") | D16: =IFERROR(AVERAGEIFS($H$37:$H$256,$A$37:$A$256,"ETH → SOL",$C$37:$C$256,$A16),"n/a") | E16: =IFERROR(AVERAGEIFS($H$37:$H$256,$A$37:$A$256,"SOL → BSC",$C$37:$C$256,$A16),"n/a") | F16: =IFERROR(AVERAGEIFS($H$37:$H$256,$A$37:$A$256,"BSC → SOL",$C$37:$C$256,$A16),"n/a") | G16: =IFERROR(AVERAGEIFS($H$37:$H$256,$A$37:$A$256,"SOL → Base",$C$37:$C$256,$A16),"n/a") | H16: =IFERROR(AVERAGEIFS($H$37:$H$256,$A$37:$A$256,"Base → SOL",$C$37:$C$256,$A16),"n/a") | N16: Meson | O16: =IFERROR(AVERAGEIFS($G$37:$G$256,$A$37:$A$256,"SOL → ETH",$C$37:$C$256,$N16),"") | P16: =IFERROR(AVERAGEIFS($G$37:$G$256,$A$37:$A$256,"ETH → SOL",$C$37:$C$256,$N16),"") | Q16: =IFERROR(AVERAGEIFS($G$37:$G$256,$A$37:$A$256,"SOL → BSC",$C$37:$C$256,$N16),"") | R16: =IFERROR(AVERAGEIFS($G$37:$G$256,$A$37:$A$256,"BSC → SOL",$C$37:$C$256,$N16),"") | S16: =IFERROR(AVERAGEIFS($G$37:$G$256,$A$37:$A$256,"SOL → Base",$C$37:$C$256,$N16),"") | T16: =IFERROR(AVERAGEIFS($G$37:$G$256,$A$37:$A$256,"Base → SOL",$C$37:$C$256,$N16),"")
A17: SimpleSwap | B17: venue | C17: =IFERROR(AVERAGEIFS($H$37:$H$256,$A$37:$A$256,"SOL → ETH",$C$37:$C$256,$A17),"n/a") | D17: =IFERROR(AVERAGEIFS($H$37:$H$256,$A$37:$A$256,"ETH → SOL",$C$37:$C$256,$A17),"n/a") | E17: =IFERROR(AVERAGEIFS($H$37:$H$256,$A$37:$A$256,"SOL → BSC",$C$37:$C$256,$A17),"n/a") | F17: =IFERROR(AVERAGEIFS($H$37:$H$256,$A$37:$A$256,"BSC → SOL",$C$37:$C$256,$A17),"n/a") | G17: =IFERROR(AVERAGEIFS($H$37:$H$256,$A$37:$A$256,"SOL → Base",$C$37:$C$256,$A17),"n/a") | H17: =IFERROR(AVERAGEIFS($H$37:$H$256,$A$37:$A$256,"Base → SOL",$C$37:$C$256,$A17),"n/a") | N17: SimpleSwap | O17: =IFERROR(AVERAGEIFS($G$37:$G$256,$A$37:$A$256,"SOL → ETH",$C$37:$C$256,$N17),"") | P17: =IFERROR(AVERAGEIFS($G$37:$G$256,$A$37:$A$256,"ETH → SOL",$C$37:$C$256,$N17),"") | Q17: =IFERROR(AVERAGEIFS($G$37:$G$256,$A$37:$A$256,"SOL → BSC",$C$37:$C$256,$N17),"") | R17: =IFERROR(AVERAGEIFS($G$37:$G$256,$A$37:$A$256,"BSC → SOL",$C$37:$C$256,$N17),"") | S17: =IFERROR(AVERAGEIFS($G$37:$G$256,$A$37:$A$256,"SOL → Base",$C$37:$C$256,$N17),"") | T17: =IFERROR(AVERAGEIFS($G$37:$G$256,$A$37:$A$256,"Base → SOL",$C$37:$C$256,$N17),"")
... A19: Symbiosis | B19: venue | C19: =IFERROR(AVERAGEIFS($H$37:$H$256,$A$37:$A$256,"SOL → ETH",$C$37:$C$256,$A19),"n/a") | D19: =IFERROR(AVERAGEIFS($H$37:$H$256,$A$37:$A$256,"ETH → SOL",$C$37:$C$256,$A19),"n/a") | E19: =IFERROR(AVERAGEIFS($H$37:$H$256,$A$37:$A$256,"SOL → BSC",$C$37:$C$256,$A19),"n/a") | F19: =IFERROR(AVERAGEIFS($H$37:$H$256,$A$37:$A$256,"BSC → SOL",$C$37:$C$256,$A19),"n/a") | G19: =IFERROR(AVERAGEIFS($H$37:$H$256,$A$37:$A$256,"SOL → Base",$C$37:$C$256,$A19),"n/a") | H19: =IFERROR(AVERAGEIFS($H$37:$H$256,$A$37:$A$256,"Base → SOL",$C$37:$C$256,$A19),"n/a") | N19: Symbiosis | O19: =IFERROR(AVERAGEIFS($G$37:$G$256,$A$37:$A$256,"SOL → ETH",$C$37:$C$256,$N19),"") | P19: =IFERROR(AVERAGEIFS($G$37:$G$256,$A$37:$A$256,"ETH → SOL",$C$37:$C$256,$N19),"") | Q19: =IFERROR(AVERAGEIFS($G$37:$G$256,$A$37:$A$256,"SOL → BSC",$C$37:$C$256,$N19),"") | R19: =IFERROR(AVERAGEIFS($G$37:$G$256,$A$37:$A$256,"BSC → SOL",$C$37:$C$256,$N19),"") | S19: =IFERROR(AVERAGEIFS($G$37:$G$256,$A$37:$A$256,"SOL → Base",$C$37:$C$256,$N19),"") | T19: =IFERROR(AVERAGEIFS($G$37:$G$256,$A$37:$A$256,"Base → SOL",$C$37:$C$256,$N19),"")
A20: Axiom | B20: platform | C20: BLOCKED — PARTIAL — no 100 USDC quote without funds. Signed-in check (user logged in; built-in browser, 2026-09-23): Axiom 'Exchange' has a cross-chain Convert (e.g. 'Swap USDC on Solana for USDC on Ethereum', indicative 1 USDC = 1.0000 USDC) but the amount field clamps to the wallet balance (0), so 100 can't be priced. Deposit auto-bridges EVM→Solana and shows fees only at its minimum: ETH→SOL USDC ($3 min) ~26s, impact −0.388%, fees ~$0.27 (gas $0.27, routing/liquidity <$0.01); BSC→SOL ($2 min) ~26s, impact −8.357%, fees ~$0.21 (gas); Base→SOL ($2 min) ~26s, impact −0.455%, fees ~$0.02. Indicative only — not comparable to a 100 USDC quote.
A21: FOMO | B21: platform | C21: BLOCKED — BLOCKED — signed-in check (user logged in): deposits accept USDC from Solana, Base, BNB Chain, Monad, Robinhood Chain, Arc, Ethereum into one USD cash balance; no fee/quote is shown at deposit and moving funds out needs a balance. No chain-to-chain quote.
A22: GMGN | B22: platform | C22: BLOCKED — BLOCKED — signed-in check (user logged in): wallet menu has Convert, but it requires binding 2FA (a security-setting change the user must make) and then a 3-hour lock before Convert works. Deposit accepts SOL/USDT/USDC/USD1 on the Solana network only.
A23: Pump.fun | B23: platform | C23: BLOCKED — BLOCKED — signed-in check (user logged in): web Deposit is Solana-only ('Only send assets on the Solana network', min 0.01 SOL). No cross-chain quote on web; the MoonPay cross-chain deposit reported in news may be mobile-only.
A26: Route winners
A27: Route | B27: Bridg best (avg) | C27: Best elsewhere (avg out) | D27: Site | E27: Bridg vs best (bps) | F27: Sites Bridg beats | G27: Sites beating Bridg
A28: SOL → ETH | B28: =IFERROR(AVERAGEIFS('Raw Quotes'!$K:$K,'Raw Quotes'!$B:$B,"SOL->ETH",'Raw Quotes'!$D:$D,"Bridg",'Raw Quotes'!$F:$F,"OK"),"") | C28: =MAX($O$6:$O$19) | D28: =INDEX($N$6:$N$19,MATCH(C28,$O$6:$O$19,0)) | E28: =(B28-C28)/100*10000 | F28: =COUNTIF($C$6:$C$19,">2") | G28: =COUNTIF($C$6:$C$19,"<-2") | H28: Bridg best is averaged per synchronized run (Raw Quotes); savings compare it with the best per-site average.
A29: ETH → SOL | B29: =IFERROR(AVERAGEIFS('Raw Quotes'!$K:$K,'Raw Quotes'!$B:$B,"ETH->SOL",'Raw Quotes'!$D:$D,"Bridg",'Raw Quotes'!$F:$F,"OK"),"") | C29: =MAX($P$6:$P$19) | D29: =INDEX($N$6:$N$19,MATCH(C29,$P$6:$P$19,0)) | E29: =(B29-C29)/100*10000 | F29: =COUNTIF($D$6:$D$19,">2") | G29: =COUNTIF($D$6:$D$19,"<-2")
A30: SOL → BSC | B30: =IFERROR(AVERAGEIFS('Raw Quotes'!$K:$K,'Raw Quotes'!$B:$B,"SOL->BSC",'Raw Quotes'!$D:$D,"Bridg",'Raw Quotes'!$F:$F,"OK"),"") | C30: =MAX($Q$6:$Q$19) | D30: =INDEX($N$6:$N$19,MATCH(C30,$Q$6:$Q$19,0)) | E30: =(B30-C30)/100*10000 | F30: =COUNTIF($E$6:$E$19,">2") | G30: =COUNTIF($E$6:$E$19,"<-2")
A31: BSC → SOL | B31: =IFERROR(AVERAGEIFS('Raw Quotes'!$K:$K,'Raw Quotes'!$B:$B,"BSC->SOL",'Raw Quotes'!$D:$D,"Bridg",'Raw Quotes'!$F:$F,"OK"),"") | C31: =MAX($R$6:$R$19) | D31: =INDEX($N$6:$N$19,MATCH(C31,$R$6:$R$19,0)) | E31: =(B31-C31)/100*10000 | F31: =COUNTIF($F$6:$F$19,">2") | G31: =COUNTIF($F$6:$F$19,"<-2")
A32: SOL → Base | B32: =IFERROR(AVERAGEIFS('Raw Quotes'!$K:$K,'Raw Quotes'!$B:$B,"SOL->Base",'Raw Quotes'!$D:$D,"Bridg",'Raw Quotes'!$F:$F,"OK"),"") | C32: =MAX($S$6:$S$19) | D32: =INDEX($N$6:$N$19,MATCH(C32,$S$6:$S$19,0)) | E32: =(B32-C32)/100*10000 | F32: =COUNTIF($G$6:$G$19,">2") | G32: =COUNTIF($G$6:$G$19,"<-2")
A33: Base → SOL | B33: =IFERROR(AVERAGEIFS('Raw Quotes'!$K:$K,'Raw Quotes'!$B:$B,"Base->SOL",'Raw Quotes'!$D:$D,"Bridg",'Raw Quotes'!$F:$F,"OK"),"") | C33: =MAX($T$6:$T$19) | D33: =INDEX($N$6:$N$19,MATCH(C33,$T$6:$T$19,0)) | E33: =(B33-C33)/100*10000 | F33: =COUNTIF($H$6:$H$19,">2") | G33: =COUNTIF($H$6:$H$19,"<-2")
A35: Per-sample observations
A36: Route | B36: Sample | C36: Site | D36: Kind | E36: Bridg best | F36: Bridg best via | G36: Other out (cmp) | H36: Savings bps | I36: Fee on top in SOL/ETH (not counted) | J36: Bridg value read (UTC) | K36: Other value read (UTC) | L36: Δ read (s)
A37: SOL → ETH | B37: 1 | C37: OpenSea | D37: platform | E37: 99.840015 | F37: Across | G37: 98.9896 | H37: =(E37-G37)/100*10000 | I37: yes | J37: 2026-09-23T14:18:55.406Z | K37: 2026-09-23T14:18:55.405Z | L37: 0.001
A38: SOL → ETH | B38: 2 | C38: OpenSea | D38: platform | E38: 99.840015 | F38: Across | G38: 98.7874 | H38: =(E38-G38)/100*10000 | J38: 2026-09-23T14:22:28.648Z | K38: 2026-09-23T14:22:28.640Z | L38: 0.008
A39: SOL → ETH | B39: 3 | C39: OpenSea | D39: platform | E39: 99.840015 | F39: Across | G39: 99.067 | H39: =(E39-G39)/100*10000 | I39: yes | J39: 2026-09-23T14:26:54.591Z | K39: 2026-09-23T14:26:54.593Z | L39: 0.002
A40: SOL → ETH | B40: 1 | C40: Relay | D40: venue | E40: 99.840015 | F40: Across | G40: 99.193956 | H40: =(E40-G40)/100*10000 | J40: 2026-09-23T14:18:55.406Z | K40: 2026-09-23T14:18:55.404Z | L40: 0.002
A41: SOL → ETH | B41: 2 | C41: Relay | D41: venue | E41: 99.840015 | F41: Across | G41: 99.087326 | H41: =(E41-G41)/100*10000 | J41: 2026-09-23T14:22:28.648Z | K41: 2026-09-23T14:22:28.645Z | L41: 0.003
A42: SOL → ETH | B42: 3 | C42: Relay | D42: venue | E42: 99.840015 | F42: Across | G42: 99.260036 | H42: =(E42-G42)/100*10000 | J42: 2026-09-23T14:26:54.591Z | K42: 2026-09-23T14:26:54.589Z | L42: 0.002
A43: SOL → ETH | B43: 1 | C43: deBridge | D43: venue | E43: 99.840015 | F43: Across | G43: 96.984618 | H43: =(E43-G43)/100*10000 | J43: 2026-09-23T14:18:55.406Z | K43: 2026-09-23T14:18:55.402Z | L43: 0.004
A44: SOL → ETH | B44: 2 | C44: deBridge | D44: venue | E44: 99.840015 | F44: Across | G44: 96.646618 | H44: =(E44-G44)/100*10000 | J44: 2026-09-23T14:22:28.648Z | K44: 2026-09-23T14:22:28.646Z | L44: 0.002
A45: SOL → ETH | B45: 3 | C45: deBridge | D45: venue | E45: 99.840015 | F45: Across | G45: 97.060133 | H45: =(E45-G45)/100*10000 | J45: 2026-09-23T14:26:54.591Z | K45: 2026-09-23T14:26:54.593Z | L45: 0.002
...

Sheet Venue Analysis
A1: Venue Analysis — is Bridg's listed quote for each venue the same as the venue's own site?
A2: Gap (bps) = (Bridg listed − venue direct) / 100 × 10,000. Ex-fee adds Bridg's platform fee back. Direct = venue out − any USDC fee charged on top of the 100 input. Blue = observed inputs; black = formulas.
A4: Route | B4: Sample | C4: Venue | D4: Bridg listed | E4: Compare only | F4: Venue out | G4: USDC fee on top | H4: Direct (cmp) | I4: Gap bps | J4: Bridg fee (USDC) | K4: Gap ex-fee bps | L4: Δ read (s) | M4: Note | N4: Bridg value read (UTC) | O4: Venue value read (UTC) | Q4: Route | R4: Venue | S4: Samples | T4: Listed on Bridg | U4: Bridg avg | V4: Direct avg | W4: Gap bps (avg) | X4: Ex-fee bps (avg) | Y4: Tolerance bps | Z4: Verdict
A5: SOL → ETH | B5: 1 | C5: Relay | D5: 98.880917 | F5: 99.193956 | H5: =IF(ISNUMBER(F5),F5-N(G5),"") | I5: =IF(AND(ISNUMBER(D5),ISNUMBER(H5)),(D5-H5)/100*10000,"") | J5: 0.05 | K5: =IF(ISNUMBER(I5),I5+N(J5)/100*10000,"") | L5: 0.002 | N5: 2026-09-23T14:18:55.406Z | O5: 2026-09-23T14:18:55.404Z | Q5: SOL → ETH | R5: Relay | S5: =COUNTIFS($A$5:$A$214,Q5,$C$5:$C$214,R5) | T5: =COUNTIFS($A$5:$A$214,Q5,$C$5:$C$214,R5,$D$5:$D$214,">0") | U5: =IFERROR(AVERAGEIFS($D$5:$D$214,$A$5:$A$214,Q5,$C$5:$C$214,R5),"—") | V5: =IFERROR(AVERAGEIFS($H$5:$H$214,$A$5:$A$214,Q5,$C$5:$C$214,R5),"—") | W5: =IFERROR(AVERAGEIFS($I$5:$I$214,$A$5:$A$214,Q5,$C$5:$C$214,R5),"—") | X5: =IFERROR(AVERAGEIFS($K$5:$K$214,$A$5:$A$214,Q5,$C$5:$C$214,R5),"—") | Y5: 2 | Z5: =IF(T5=0,"NOT LISTED on Bridg",IF(NOT(ISNUMBER(X5)),"No direct quote",IF(ABS(X5)<=Y5,"Match (net of Bridg fee)",IF(ABS(W5)<=Y5,"Match (Bridg fee not applied)",IF(X5<0,"Bridg LOWER than venue","Bridg HIGHER than venue")))))
A6: SOL → ETH | B6: 2 | C6: Relay | D6: 98.744355 | F6: 99.087326 | H6: =IF(ISNUMBER(F6),F6-N(G6),"") | I6: =IF(AND(ISNUMBER(D6),ISNUMBER(H6)),(D6-H6)/100*10000,"") | J6: 0.05 | K6: =IF(ISNUMBER(I6),I6+N(J6)/100*10000,"") | L6: 0.003 | N6: 2026-09-23T14:22:28.648Z | O6: 2026-09-23T14:22:28.645Z | Q6: SOL → ETH | R6: deBridge | S6: =COUNTIFS($A$5:$A$214,Q6,$C$5:$C$214,R6) | T6: =COUNTIFS($A$5:$A$214,Q6,$C$5:$C$214,R6,$D$5:$D$214,">0") | U6: =IFERROR(AVERAGEIFS($D$5:$D$214,$A$5:$A$214,Q6,$C$5:$C$214,R6),"—") | V6: =IFERROR(AVERAGEIFS($H$5:$H$214,$A$5:$A$214,Q6,$C$5:$C$214,R6),"—") | W6: =IFERROR(AVERAGEIFS($I$5:$I$214,$A$5:$A$214,Q6,$C$5:$C$214,R6),"—") | X6: =IFERROR(AVERAGEIFS($K$5:$K$214,$A$5:$A$214,Q6,$C$5:$C$214,R6),"—") | Y6: 2 | Z6: =IF(T6=0,"NOT LISTED on Bridg",IF(NOT(ISNUMBER(X6)),"No direct quote",IF(ABS(X6)<=Y6,"Match (net of Bridg fee)",IF(ABS(W6)<=Y6,"Match (Bridg fee not applied)",IF(X6<0,"Bridg LOWER than venue","Bridg HIGHER than venue")))))
A7: SOL → ETH | B7: 3 | C7: Relay | D7: 99.017721 | F7: 99.260036 | H7: =IF(ISNUMBER(F7),F7-N(G7),"") | I7: =IF(AND(ISNUMBER(D7),ISNUMBER(H7)),(D7-H7)/100*10000,"") | J7: 0.05 | K7: =IF(ISNUMBER(I7),I7+N(J7)/100*10000,"") | L7: 0.002 | N7: 2026-09-23T14:26:54.591Z | O7: 2026-09-23T14:26:54.589Z | Q7: SOL → ETH | R7: LI.FI (Jumper) | S7: =COUNTIFS($A$5:$A$214,Q7,$C$5:$C$214,R7) | T7: =COUNTIFS($A$5:$A$214,Q7,$C$5:$C$214,R7,$D$5:$D$214,">0") | U7: =IFERROR(AVERAGEIFS($D$5:$D$214,$A$5:$A$214,Q7,$C$5:$C$214,R7),"—") | V7: =IFERROR(AVERAGEIFS($H$5:$H$214,$A$5:$A$214,Q7,$C$5:$C$214,R7),"—") | W7: =IFERROR(AVERAGEIFS($I$5:$I$214,$A$5:$A$214,Q7,$C$5:$C$214,R7),"—") | X7: =IFERROR(AVERAGEIFS($K$5:$K$214,$A$5:$A$214,Q7,$C$5:$C$214,R7),"—") | Y7: 2 | Z7: =IF(T7=0,"NOT LISTED on Bridg",IF(NOT(ISNUMBER(X7)),"No direct quote",IF(ABS(X7)<=Y7,"Match (net of Bridg fee)",IF(ABS(W7)<=Y7,"Match (Bridg fee not applied)",IF(X7<0,"Bridg LOWER than venue","Bridg HIGHER than venue")))))
A8: SOL → ETH | B8: 1 | C8: deBridge | D8: 96.986978 | F8: 99.920018 | G8: 2.9354 | H8: =IF(ISNUMBER(F8),F8-N(G8),"") | I8: =IF(AND(ISNUMBER(D8),ISNUMBER(H8)),(D8-H8)/100*10000,"") | J8: 0.15 | K8: =IF(ISNUMBER(I8),I8+N(J8)/100*10000,"") | L8: 0.004 | M8: +2.9354 USDC charged on top of 100 input (subtracted) | N8: 2026-09-23T14:18:55.406Z | O8: 2026-09-23T14:18:55.402Z | Q8: SOL → ETH | R8: Across | S8: =COUNTIFS($A$5:$A$214,Q8,$C$5:$C$214,R8) | T8: =COUNTIFS($A$5:$A$214,Q8,$C$5:$C$214,R8,$D$5:$D$214,">0") | U8: =IFERROR(AVERAGEIFS($D$5:$D$214,$A$5:$A$214,Q8,$C$5:$C$214,R8),"—") | V8: =IFERROR(AVERAGEIFS($H$5:$H$214,$A$5:$A$214,Q8,$C$5:$C$214,R8),"—") | W8: =IFERROR(AVERAGEIFS($I$5:$I$214,$A$5:$A$214,Q8,$C$5:$C$214,R8),"—") | X8: =IFERROR(AVERAGEIFS($K$5:$K$214,$A$5:$A$214,Q8,$C$5:$C$214,R8),"—") | Y8: 2 | Z8: =IF(T8=0,"NOT LISTED on Bridg",IF(NOT(ISNUMBER(X8)),"No direct quote",IF(ABS(X8)<=Y8,"Match (net of Bridg fee)",IF(ABS(W8)<=Y8,"Match (Bridg fee not applied)",IF(X8<0,"Bridg LOWER than venue","Bridg HIGHER than venue")))))
A9: SOL → ETH | B9: 2 | C9: deBridge | D9: 96.649264 | F9: 99.920018 | G9: 3.2734 | H9: =IF(ISNUMBER(F9),F9-N(G9),"") | I9: =IF(AND(ISNUMBER(D9),ISNUMBER(H9)),(D9-H9)/100*10000,"") | J9: 0.15 | K9: =IF(ISNUMBER(I9),I9+N(J9)/100*10000,"") | L9: 0.002 | M9: +3.2734 USDC charged on top of 100 input (subtracted) | N9: 2026-09-23T14:22:28.648Z | O9: 2026-09-23T14:22:28.646Z | Q9: SOL → ETH | R9: Mayan | S9: =COUNTIFS($A$5:$A$214,Q9,$C$5:$C$214,R9) | T9: =COUNTIFS($A$5:$A$214,Q9,$C$5:$C$214,R9,$D$5:$D$214,">0") | U9: =IFERROR(AVERAGEIFS($D$5:$D$214,$A$5:$A$214,Q9,$C$5:$C$214,R9),"—") | V9: =IFERROR(AVERAGEIFS($H$5:$H$214,$A$5:$A$214,Q9,$C$5:$C$214,R9),"—") | W9: =IFERROR(AVERAGEIFS($I$5:$I$214,$A$5:$A$214,Q9,$C$5:$C$214,R9),"—") | X9: =IFERROR(AVERAGEIFS($K$5:$K$214,$A$5:$A$214,Q9,$C$5:$C$214,R9),"—") | Y9: 4 | Z9: =IF(T9=0,"NOT LISTED on Bridg",IF(NOT(ISNUMBER(X9)),"No direct quote",IF(ABS(X9)<=Y9,"Match (net of Bridg fee)",IF(ABS(W9)<=Y9,"Match (Bridg fee not applied)",IF(X9<0,"Bridg LOWER than venue","Bridg HIGHER than venue")))))
A10: SOL → ETH | B10: 3 | C10: deBridge | D10: 97.026152 | F10: 99.880033 | G10: 2.8199 | H10: =IF(ISNUMBER(F10),F10-N(G10),"") | I10: =IF(AND(ISNUMBER(D10),ISNUMBER(H10)),(D10-H10)/100*10000,"") | J10: 0.15 | K10: =IF(ISNUMBER(I10),I10+N(J10)/100*10000,"") | L10: 0.002 | M10: +2.8199 USDC charged on top of 100 input (subtracted) | N10: 2026-09-23T14:26:54.591Z | O10: 2026-09-23T14:26:54.593Z | Q10: SOL → ETH | R10: Allbridge Core | S10: =COUNTIFS($A$5:$A$214,Q10,$C$5:$C$214,R10) | T10: =COUNTIFS($A$5:$A$214,Q10,$C$5:$C$214,R10,$D$5:$D$214,">0") | U10: =IFERROR(AVERAGEIFS($D$5:$D$214,$A$5:$A$214,Q10,$C$5:$C$214,R10),"—") | V10: =IFERROR(AVERAGEIFS($H$5:$H$214,$A$5:$A$214,Q10,$C$5:$C$214,R10),"—") | W10: =IFERROR(AVERAGEIFS($I$5:$I$214,$A$5:$A$214,Q10,$C$5:$C$214,R10),"—") | X10: =IFERROR(AVERAGEIFS($K$5:$K$214,$A$5:$A$214,Q10,$C$5:$C$214,R10),"—") | Y10: 2 | Z10: =IF(T10=0,"NOT LISTED on Bridg",IF(NOT(ISNUMBER(X10)),"No direct quote",IF(ABS(X10)<=Y10,"Match (net of Bridg fee)",IF(ABS(W10)<=Y10,"Match (Bridg fee not applied)",IF(X10<0,"Bridg LOWER than venue","Bridg HIGHER than venue")))))
A11: SOL → ETH | B11: 1 | C11: LI.FI (Jumper) | D11: 98.887005 | F11: 99.193956 | H11: =IF(ISNUMBER(F11),F11-N(G11),"") | I11: =IF(AND(ISNUMBER(D11),ISNUMBER(H11)),(D11-H11)/100*10000,"") | J11: 0.15 | K11: =IF(ISNUMBER(I11),I11+N(J11)/100*10000,"") | L11: 0.006 | M11: Jumper Best Return via Relay; max route 99.99 | N11: 2026-09-23T14:18:55.406Z | O11: 2026-09-23T14:18:55.400Z | Q11: SOL → ETH | R11: CCTP (via Portal) | S11: =COUNTIFS($A$5:$A$214,Q11,$C$5:$C$214,R11) | T11: =COUNTIFS($A$5:$A$214,Q11,$C$5:$C$214,R11,$D$5:$D$214,">0") | U11: =IFERROR(AVERAGEIFS($D$5:$D$214,$A$5:$A$214,Q11,$C$5:$C$214,R11),"—") | V11: =IFERROR(AVERAGEIFS($H$5:$H$214,$A$5:$A$214,Q11,$C$5:$C$214,R11),"—") | W11: =IFERROR(AVERAGEIFS($I$5:$I$214,$A$5:$A$214,Q11,$C$5:$C$214,R11),"—") | X11: =IFERROR(AVERAGEIFS($K$5:$K$214,$A$5:$A$214,Q11,$C$5:$C$214,R11),"—") | Y11: 2 | Z11: =IF(T11=0,"NOT LISTED on Bridg",IF(NOT(ISNUMBER(X11)),"No direct quote",IF(ABS(X11)<=Y11,"Match (net of Bridg fee)",IF(ABS(W11)<=Y11,"Match (Bridg fee not applied)",IF(X11<0,"Bridg LOWER than venue","Bridg HIGHER than venue")))))
A12: SOL → ETH | B12: 2 | C12: LI.FI (Jumper) | D12: 98.889246 | F12: 99.087326 | H12: =IF(ISNUMBER(F12),F12-N(G12),"") | I12: =IF(AND(ISNUMBER(D12),ISNUMBER(H12)),(D12-H12)/100*10000,"") | J12: 0.15 | K12: =IF(ISNUMBER(I12),I12+N(J12)/100*10000,"") | L12: 0.002 | M12: Jumper Best Return via Relay; max route 99.99 | N12: 2026-09-23T14:22:28.648Z | O12: 2026-09-23T14:22:28.650Z | Q12: SOL → ETH | R12: Husher | S12: =COUNTIFS($A$5:$A$214,Q12,$C$5:$C$214,R12) | T12: =COUNTIFS($A$5:$A$214,Q12,$C$5:$C$214,R12,$D$5:$D$214,">0") | U12: =IFERROR(AVERAGEIFS($D$5:$D$214,$A$5:$A$214,Q12,$C$5:$C$214,R12),"—") | V12: =IFERROR(AVERAGEIFS($H$5:$H$214,$A$5:$A$214,Q12,$C$5:$C$214,R12),"—") | W12: =IFERROR(AVERAGEIFS($I$5:$I$214,$A$5:$A$214,Q12,$C$5:$C$214,R12),"—") | X12: =IFERROR(AVERAGEIFS($K$5:$K$214,$A$5:$A$214,Q12,$C$5:$C$214,R12),"—") | Y12: 2 | Z12: =IF(T12=0,"NOT LISTED on Bridg",IF(NOT(ISNUMBER(X12)),"No direct quote",IF(ABS(X12)<=Y12,"Match (net of Bridg fee)",IF(ABS(W12)<=Y12,"Match (Bridg fee not applied)",IF(X12<0,"Bridg LOWER than venue","Bridg HIGHER than venue")))))
A13: SOL → ETH | B13: 3 | C13: LI.FI (Jumper) | D13: 98.86696 | F13: 99.260036 | H13: =IF(ISNUMBER(F13),F13-N(G13),"") | I13: =IF(AND(ISNUMBER(D13),ISNUMBER(H13)),(D13-H13)/100*10000,"") | J13: 0.15 | K13: =IF(ISNUMBER(I13),I13+N(J13)/100*10000,"") | L13: 0 | M13: Jumper Best Return via Relay; max route 99.99 | N13: 2026-09-23T14:26:54.591Z | O13: 2026-09-23T14:26:54.591Z | Q13: SOL → ETH | R13: Layerswap | S13: =COUNTIFS($A$5:$A$214,Q13,$C$5:$C$214,R13) | T13: =COUNTIFS($A$5:$A$214,Q13,$C$5:$C$214,R13,$D$5:$D$214,">0") | U13: =IFERROR(AVERAGEIFS($D$5:$D$214,$A$5:$A$214,Q13,$C$5:$C$214,R13),"—") | V13: =IFERROR(AVERAGEIFS($H$5:$H$214,$A$5:$A$214,Q13,$C$5:$C$214,R13),"—") | W13: =IFERROR(AVERAGEIFS($I$5:$I$214,$A$5:$A$214,Q13,$C$5:$C$214,R13),"—") | X13: =IFERROR(AVERAGEIFS($K$5:$K$214,$A$5:$A$214,Q13,$C$5:$C$214,R13),"—") | Y13: 2 | Z13: =IF(T13=0,"NOT LISTED on Bridg",IF(NOT(ISNUMBER(X13)),"No direct quote",IF(ABS(X13)<=Y13,"Match (net of Bridg fee)",IF(ABS(W13)<=Y13,"Match (Bridg fee not applied)",IF(X13<0,"Bridg LOWER than venue","Bridg HIGHER than venue")))))
A14: SOL → ETH | B14: 1 | C14: Across | D14: 99.840015 | F14: 99.99 | H14: =IF(ISNUMBER(F14),F14-N(G14),"") | I14: =IF(AND(ISNUMBER(D14),ISNUMBER(H14)),(D14-H14)/100*10000,"") | J14: 0.15 | K14: =IF(ISNUMBER(I14),I14+N(J14)/100*10000,"") | L14: 0.006 | N14: 2026-09-23T14:18:55.406Z | O14: 2026-09-23T14:18:55.400Z | Q14: SOL → ETH | R14: Meson | S14: =COUNTIFS($A$5:$A$214,Q14,$C$5:$C$214,R14) | T14: =COUNTIFS($A$5:$A$214,Q14,$C$5:$C$214,R14,$D$5:$D$214,">0") | U14: =IFERROR(AVERAGEIFS($D$5:$D$214,$A$5:$A$214,Q14,$C$5:$C$214,R14),"—") | V14: =IFERROR(AVERAGEIFS($H$5:$H$214,$A$5:$A$214,Q14,$C$5:$C$214,R14),"—") | W14: =IFERROR(AVERAGEIFS($I$5:$I$214,$A$5:$A$214,Q14,$C$5:$C$214,R14),"—") | X14: =IFERROR(AVERAGEIFS($K$5:$K$214,$A$5:$A$214,Q14,$C$5:$C$214,R14),"—") | Y14: 2 | Z14: =IF(T14=0,"NOT LISTED on Bridg",IF(NOT(ISNUMBER(X14)),"No direct quote",IF(ABS(X14)<=Y14,"Match (net of Bridg fee)",IF(ABS(W14)<=Y14,"Match (Bridg fee not applied)",IF(X14<0,"Bridg LOWER than venue","Bridg HIGHER than venue")))))
A15: SOL → ETH | B15: 2 | C15: Across | D15: 99.840015 | F15: 99.99 | H15: =IF(ISNUMBER(F15),F15-N(G15),"") | I15: =IF(AND(ISNUMBER(D15),ISNUMBER(H15)),(D15-H15)/100*10000,"") | J15: 0.15 | K15: =IF(ISNUMBER(I15),I15+N(J15)/100*10000,"") | L15: 0.004 | N15: 2026-09-23T14:22:28.648Z | O15: 2026-09-23T14:22:28.644Z | Q15: SOL → ETH | R15: SimpleSwap | S15: =COUNTIFS($A$5:$A$214,Q15,$C$5:$C$214,R15) | T15: =COUNTIFS($A$5:$A$214,Q15,$C$5:$C$214,R15,$D$5:$D$214,">0") | U15: =IFERROR(AVERAGEIFS($D$5:$D$214,$A$5:$A$214,Q15,$C$5:$C$214,R15),"—") | V15: =IFERROR(AVERAGEIFS($H$5:$H$214,$A$5:$A$214,Q15,$C$5:$C$214,R15),"—") | W15: =IFERROR(AVERAGEIFS($I$5:$I$214,$A$5:$A$214,Q15,$C$5:$C$214,R15),"—") | X15: =IFERROR(AVERAGEIFS($K$5:$K$214,$A$5:$A$214,Q15,$C$5:$C$214,R15),"—") | Y15: 2 | Z15: =IF(T15=0,"NOT LISTED on Bridg",IF(NOT(ISNUMBER(X15)),"No direct quote",IF(ABS(X15)<=Y15,"Match (net of Bridg fee)",IF(ABS(W15)<=Y15,"Match (Bridg fee not applied)",IF(X15<0,"Bridg LOWER than venue","Bridg HIGHER than venue")))))
A16: SOL → ETH | B16: 3 | C16: Across | D16: 99.840015 | F16: 99.99 | H16: =IF(ISNUMBER(F16),F16-N(G16),"") | I16: =IF(AND(ISNUMBER(D16),ISNUMBER(H16)),(D16-H16)/100*10000,"") | J16: 0.15 | K16: =IF(ISNUMBER(I16),I16+N(J16)/100*10000,"") | L16: 0.002 | N16: 2026-09-23T14:26:54.591Z | O16: 2026-09-23T14:26:54.589Z | Q16: SOL → ETH | R16: Skip Go | S16: =COUNTIFS($A$5:$A$214,Q16,$C$5:$C$214,R16) | T16: =COUNTIFS($A$5:$A$214,Q16,$C$5:$C$214,R16,$D$5:$D$214,">0") | U16: =IFERROR(AVERAGEIFS($D$5:$D$214,$A$5:$A$214,Q16,$C$5:$C$214,R16),"—") | V16: =IFERROR(AVERAGEIFS($H$5:$H$214,$A$5:$A$214,Q16,$C$5:$C$214,R16),"—") | W16: =IFERROR(AVERAGEIFS($I$5:$I$214,$A$5:$A$214,Q16,$C$5:$C$214,R16),"—") | X16: =IFERROR(AVERAGEIFS($K$5:$K$214,$A$5:$A$214,Q16,$C$5:$C$214,R16),"—") | Y16: 2 | Z16: =IF(T16=0,"NOT LISTED on Bridg",IF(NOT(ISNUMBER(X16)),"No direct quote",IF(ABS(X16)<=Y16,"Match (net of Bridg fee)",IF(ABS(W16)<=Y16,"Match (Bridg fee not applied)",IF(X16<0,"Bridg LOWER than venue","Bridg HIGHER than venue")))))
A17: SOL → ETH | B17: 1 | C17: Mayan | D17: 96.488949 | E17: yes | F17: 96.6446 | H17: =IF(ISNUMBER(F17),F17-N(G17),"") | I17: =IF(AND(ISNUMBER(D17),ISNUMBER(H17)),(D17-H17)/100*10000,"") | J17: 0.15 | K17: =IF(ISNUMBER(I17),I17+N(J17)/100*10000,"") | L17: 0.006 | M17: Swift v2; UI shows 4 dp | N17: 2026-09-23T14:18:55.406Z | O17: 2026-09-23T14:18:55.400Z | Q17: SOL → ETH | R17: Symbiosis | S17: =COUNTIFS($A$5:$A$214,Q17,$C$5:$C$214,R17) | T17: =COUNTIFS($A$5:$A$214,Q17,$C$5:$C$214,R17,$D$5:$D$214,">0") | U17: =IFERROR(AVERAGEIFS($D$5:$D$214,$A$5:$A$214,Q17,$C$5:$C$214,R17),"—") | V17: =IFERROR(AVERAGEIFS($H$5:$H$214,$A$5:$A$214,Q17,$C$5:$C$214,R17),"—") | W17: =IFERROR(AVERAGEIFS($I$5:$I$214,$A$5:$A$214,Q17,$C$5:$C$214,R17),"—") | X17: =IFERROR(AVERAGEIFS($K$5:$K$214,$A$5:$A$214,Q17,$C$5:$C$214,R17),"—") | Y17: 2 | Z17: =IF(T17=0,"NOT LISTED on Bridg",IF(NOT(ISNUMBER(X17)),"No direct quote",IF(ABS(X17)<=Y17,"Match (net of Bridg fee)",IF(ABS(W17)<=Y17,"Match (Bridg fee not applied)",IF(X17<0,"Bridg LOWER than venue","Bridg HIGHER than venue")))))
A18: SOL → ETH | B18: 2 | C18: Mayan | D18: 96.68446 | E18: yes | F18: 96.6844 | H18: =IF(ISNUMBER(F18),F18-N(G18),"") | I18: =IF(AND(ISNUMBER(D18),ISNUMBER(H18)),(D18-H18)/100*10000,"") | J18: 0.15 | K18: =IF(ISNUMBER(I18),I18+N(J18)/100*10000,"") | L18: 0.005 | M18: Swift v2; UI shows 4 dp | N18: 2026-09-23T14:22:28.648Z | O18: 2026-09-23T14:22:28.643Z | Q18: ETH → SOL | R18: Relay | S18: =COUNTIFS($A$5:$A$214,Q18,$C$5:$C$214,R18) | T18: =COUNTIFS($A$5:$A$214,Q18,$C$5:$C$214,R18,$D$5:$D$214,">0") | U18: =IFERROR(AVERAGEIFS($D$5:$D$214,$A$5:$A$214,Q18,$C$5:$C$214,R18),"—") | V18: =IFERROR(AVERAGEIFS($H$5:$H$214,$A$5:$A$214,Q18,$C$5:$C$214,R18),"—") | W18: =IFERROR(AVERAGEIFS($I$5:$I$214,$A$5:$A$214,Q18,$C$5:$C$214,R18),"—") | X18: =IFERROR(AVERAGEIFS($K$5:$K$214,$A$5:$A$214,Q18,$C$5:$C$214,R18),"—") | Y18: 2 | Z18: =IF(T18=0,"NOT LISTED on Bridg",IF(NOT(ISNUMBER(X18)),"No direct quote",IF(ABS(X18)<=Y18,"Match (net of Bridg fee)",IF(ABS(W18)<=Y18,"Match (Bridg fee not applied)",IF(X18<0,"Bridg LOWER than venue","Bridg HIGHER than venue")))))
A19: SOL → ETH | B19: 3 | C19: Mayan | D19: 96.851035 | E19: yes | F19: 96.851 | H19: =IF(ISNUMBER(F19),F19-N(G19),"") | I19: =IF(AND(ISNUMBER(D19),ISNUMBER(H19)),(D19-H19)/100*10000,"") | J19: 0.15 | K19: =IF(ISNUMBER(I19),I19+N(J19)/100*10000,"") | L19: 0.003 | M19: Swift v2; UI shows 3 dp | N19: 2026-09-23T14:26:54.591Z | O19: 2026-09-23T14:26:54.588Z | Q19: ETH → SOL | R19: deBridge | S19: =COUNTIFS($A$5:$A$214,Q19,$C$5:$C$214,R19) | T19: =COUNTIFS($A$5:$A$214,Q19,$C$5:$C$214,R19,$D$5:$D$214,">0") | U19: =IFERROR(AVERAGEIFS($D$5:$D$214,$A$5:$A$214,Q19,$C$5:$C$214,R19),"—") | V19: =IFERROR(AVERAGEIFS($H$5:$H$214,$A$5:$A$214,Q19,$C$5:$C$214,R19),"—") | W19: =IFERROR(AVERAGEIFS($I$5:$I$214,$A$5:$A$214,Q19,$C$5:$C$214,R19),"—") | X19: =IFERROR(AVERAGEIFS($K$5:$K$214,$A$5:$A$214,Q19,$C$5:$C$214,R19),"—") | Y19: 2 | Z19: =IF(T19=0,"NOT LISTED on Bridg",IF(NOT(ISNUMBER(X19)),"No direct quote",IF(ABS(X19)<=Y19,"Match (net of Bridg fee)",IF(ABS(W19)<=Y19,"Match (Bridg fee not applied)",IF(X19<0,"Bridg LOWER than venue","Bridg HIGHER than venue")))))
A20: SOL → ETH | B20: 1 | C20: Allbridge Core | D20: 99.75015 | E20: yes | F20: 99.9 | H20: =IF(ISNUMBER(F20),F20-N(G20),"") | I20: =IF(AND(ISNUMBER(D20),ISNUMBER(H20)),(D20-H20)/100*10000,"") | J20: 0.15 | K20: =IF(ISNUMBER(I20),I20+N(J20)/100*10000,"") | L20: 0.005 | M20: +0.014082 SOL (relayer fee, fee=native) charged on top of 100 input (not converted) | N20: 2026-09-23T14:18:55.406Z | O20: 2026-09-23T14:18:55.401Z | Q20: ETH → SOL | R20: LI.FI (Jumper) | S20: =COUNTIFS($A$5:$A$214,Q20,$C$5:$C$214,R20) | T20: =COUNTIFS($A$5:$A$214,Q20,$C$5:$C$214,R20,$D$5:$D$214,">0") | U20: =IFERROR(AVERAGEIFS($D$5:$D$214,$A$5:$A$214,Q20,$C$5:$C$214,R20),"—") | V20: =IFERROR(AVERAGEIFS($H$5:$H$214,$A$5:$A$214,Q20,$C$5:$C$214,R20),"—") | W20: =IFERROR(AVERAGEIFS($I$5:$I$214,$A$5:$A$214,Q20,$C$5:$C$214,R20),"—") | X20: =IFERROR(AVERAGEIFS($K$5:$K$214,$A$5:$A$214,Q20,$C$5:$C$214,R20),"—") | Y20: 2 | Z20: =IF(T20=0,"NOT LISTED on Bridg",IF(NOT(ISNUMBER(X20)),"No direct quote",IF(ABS(X20)<=Y20,"Match (net of Bridg fee)",IF(ABS(W20)<=Y20,"Match (Bridg fee not applied)",IF(X20<0,"Bridg LOWER than venue","Bridg HIGHER than venue")))))
A21: SOL → ETH | B21: 2 | C21: Allbridge Core | D21: 99.75015 | E21: yes | F21: 99.9 | H21: =IF(ISNUMBER(F21),F21-N(G21),"") | I21: =IF(AND(ISNUMBER(D21),ISNUMBER(H21)),(D21-H21)/100*10000,"") | J21: 0.15 | K21: =IF(ISNUMBER(I21),I21+N(J21)/100*10000,"") | L21: 0.004 | M21: +0.014082 SOL (relayer fee, fee=native) charged on top of 100 input (not converted) | N21: 2026-09-23T14:22:28.648Z | O21: 2026-09-23T14:22:28.644Z | Q21: ETH → SOL | R21: Across | S21: =COUNTIFS($A$5:$A$214,Q21,$C$5:$C$214,R21) | T21: =COUNTIFS($A$5:$A$214,Q21,$C$5:$C$214,R21,$D$5:$D$214,">0") | U21: =IFERROR(AVERAGEIFS($D$5:$D$214,$A$5:$A$214,Q21,$C$5:$C$214,R21),"—") | V21: =IFERROR(AVERAGEIFS($H$5:$H$214,$A$5:$A$214,Q21,$C$5:$C$214,R21),"—") | W21: =IFERROR(AVERAGEIFS($I$5:$I$214,$A$5:$A$214,Q21,$C$5:$C$214,R21),"—") | X21: =IFERROR(AVERAGEIFS($K$5:$K$214,$A$5:$A$214,Q21,$C$5:$C$214,R21),"—") | Y21: 2 | Z21: =IF(T21=0,"NOT LISTED on Bridg",IF(NOT(ISNUMBER(X21)),"No direct quote",IF(ABS(X21)<=Y21,"Match (net of Bridg fee)",IF(ABS(W21)<=Y21,"Match (Bridg fee not applied)",IF(X21<0,"Bridg LOWER than venue","Bridg HIGHER than venue")))))
A22: SOL → ETH | B22: 3 | C22: Allbridge Core | D22: 99.75015 | E22: yes | F22: 99.9 | H22: =IF(ISNUMBER(F22),F22-N(G22),"") | I22: =IF(AND(ISNUMBER(D22),ISNUMBER(H22)),(D22-H22)/100*10000,"") | J22: 0.15 | K22: =IF(ISNUMBER(I22),I22+N(J22)/100*10000,"") | L22: 0.001 | M22: +0.015393 SOL (relayer fee, fee=native) charged on top of 100 input (not converted) | N22: 2026-09-23T14:26:54.591Z | O22: 2026-09-23T14:26:54.590Z | Q22: ETH → SOL | R22: Mayan | S22: =COUNTIFS($A$5:$A$214,Q22,$C$5:$C$214,R22) | T22: =COUNTIFS($A$5:$A$214,Q22,$C$5:$C$214,R22,$D$5:$D$214,">0") | U22: =IFERROR(AVERAGEIFS($D$5:$D$214,$A$5:$A$214,Q22,$C$5:$C$214,R22),"—") | V22: =IFERROR(AVERAGEIFS($H$5:$H$214,$A$5:$A$214,Q22,$C$5:$C$214,R22),"—") | W22: =IFERROR(AVERAGEIFS($I$5:$I$214,$A$5:$A$214,Q22,$C$5:$C$214,R22),"—") | X22: =IFERROR(AVERAGEIFS($K$5:$K$214,$A$5:$A$214,Q22,$C$5:$C$214,R22),"—") | Y22: 4 | Z22: =IF(T22=0,"NOT LISTED on Bridg",IF(NOT(ISNUMBER(X22)),"No direct quote",IF(ABS(X22)<=Y22,"Match (net of Bridg fee)",IF(ABS(W22)<=Y22,"Match (Bridg fee not applied)",IF(X22<0,"Bridg LOWER than venue","Bridg HIGHER than venue")))))
A23: SOL → ETH | B23: 1 | C23: CCTP (via Portal) | D23: 96.584008 | E23: yes | F23: 99.99 | H23: =IF(ISNUMBER(F23),F23-N(G23),"") | I23: =IF(AND(ISNUMBER(D23),ISNUMBER(H23)),(D23-H23)/100*10000,"") | J23: 0.15 | K23: =IF(ISNUMBER(I23),I23+N(J23)/100*10000,"") | L23: 0 | M23: via Portal (CCTPv2StandardExecutorRoute); executor fee hidden until wallet connect | N23: 2026-09-23T14:18:55.406Z | O23: 2026-09-23T14:18:55.406Z | Q23: ETH → SOL | R23: Allbridge Core | S23: =COUNTIFS($A$5:$A$214,Q23,$C$5:$C$214,R23) | T23: =COUNTIFS($A$5:$A$214,Q23,$C$5:$C$214,R23,$D$5:$D$214,">0") | U23: =IFERROR(AVERAGEIFS($D$5:$D$214,$A$5:$A$214,Q23,$C$5:$C$214,R23),"—") | V23: =IFERROR(AVERAGEIFS($H$5:$H$214,$A$5:$A$214,Q23,$C$5:$C$214,R23),"—") | W23: =IFERROR(AVERAGEIFS($I$5:$I$214,$A$5:$A$214,Q23,$C$5:$C$214,R23),"—") | X23: =IFERROR(AVERAGEIFS($K$5:$K$214,$A$5:$A$214,Q23,$C$5:$C$214,R23),"—") | Y23: 2 | Z23: =IF(T23=0,"NOT LISTED on Bridg",IF(NOT(ISNUMBER(X23)),"No direct quote",IF(ABS(X23)<=Y23,"Match (net of Bridg fee)",IF(ABS(W23)<=Y23,"Match (Bridg fee not applied)",IF(X23<0,"Bridg LOWER than venue","Bridg HIGHER than venue")))))
A24: SOL → ETH | B24: 2 | C24: CCTP (via Portal) | D24: 96.584008 | E24: yes | F24: 99.99 | H24: =IF(ISNUMBER(F24),F24-N(G24),"") | I24: =IF(AND(ISNUMBER(D24),ISNUMBER(H24)),(D24-H24)/100*10000,"") | J24: 0.15 | K24: =IF(ISNUMBER(I24),I24+N(J24)/100*10000,"") | L24: 0.001 | M24: via Portal (CCTPv2StandardExecutorRoute); executor fee hidden until wallet connect | N24: 2026-09-23T14:22:28.648Z | O24: 2026-09-23T14:22:28.649Z | Q24: ETH → SOL | R24: CCTP (via Portal) | S24: =COUNTIFS($A$5:$A$214,Q24,$C$5:$C$214,R24) | T24: =COUNTIFS($A$5:$A$214,Q24,$C$5:$C$214,R24,$D$5:$D$214,">0") | U24: =IFERROR(AVERAGEIFS($D$5:$D$214,$A$5:$A$214,Q24,$C$5:$C$214,R24),"—") | V24: =IFERROR(AVERAGEIFS($H$5:$H$214,$A$5:$A$214,Q24,$C$5:$C$214,R24),"—") | W24: =IFERROR(AVERAGEIFS($I$5:$I$214,$A$5:$A$214,Q24,$C$5:$C$214,R24),"—") | X24: =IFERROR(AVERAGEIFS($K$5:$K$214,$A$5:$A$214,Q24,$C$5:$C$214,R24),"—") | Y24: 2 | Z24: =IF(T24=0,"NOT LISTED on Bridg",IF(NOT(ISNUMBER(X24)),"No direct quote",IF(ABS(X24)<=Y24,"Match (net of Bridg fee)",IF(ABS(W24)<=Y24,"Match (Bridg fee not applied)",IF(X24<0,"Bridg LOWER than venue","Bridg HIGHER than venue")))))
A25: SOL → ETH | B25: 3 | C25: CCTP (via Portal) | D25: 96.397468 | E25: yes | F25: 99.99 | H25: =IF(ISNUMBER(F25),F25-N(G25),"") | I25: =IF(AND(ISNUMBER(D25),ISNUMBER(H25)),(D25-H25)/100*10000,"") | J25: 0.15 | K25: =IF(ISNUMBER(I25),I25+N(J25)/100*10000,"") | L25: 0.003 | M25: via Portal (CCTPv2StandardExecutorRoute); executor fee hidden until wallet connect | N25: 2026-09-23T14:26:54.591Z | O25: 2026-09-23T14:26:54.588Z | Q25: ETH → SOL | R25: Husher | S25: =COUNTIFS($A$5:$A$214,Q25,$C$5:$C$214,R25) | T25: =COUNTIFS($A$5:$A$214,Q25,$C$5:$C$214,R25,$D$5:$D$214,">0") | U25: =IFERROR(AVERAGEIFS($D$5:$D$214,$A$5:$A$214,Q25,$C$5:$C$214,R25),"—") | V25: =IFERROR(AVERAGEIFS($H$5:$H$214,$A$5:$A$214,Q25,$C$5:$C$214,R25),"—") | W25: =IFERROR(AVERAGEIFS($I$5:$I$214,$A$5:$A$214,Q25,$C$5:$C$214,R25),"—") | X25: =IFERROR(AVERAGEIFS($K$5:$K$214,$A$5:$A$214,Q25,$C$5:$C$214,R25),"—") | Y25: 2 | Z25: =IF(T25=0,"NOT LISTED on Bridg",IF(NOT(ISNUMBER(X25)),"No direct quote",IF(ABS(X25)<=Y25,"Match (net of Bridg fee)",IF(ABS(W25)<=Y25,"Match (Bridg fee not applied)",IF(X25<0,"Bridg LOWER than venue","Bridg HIGHER than venue")))))
A26: SOL → ETH | B26: 1 | C26: Husher | D26: 99.1504 | F26: 99.05 | H26: =IF(ISNUMBER(F26),F26-N(G26),"") | I26: =IF(AND(ISNUMBER(D26),ISNUMBER(H26)),(D26-H26)/100*10000,"") | J26: 0.15 | K26: =IF(ISNUMBER(I26),I26+N(J26)/100*10000,"") | L26: 0.005 | N26: 2026-09-23T14:18:55.406Z | O26: 2026-09-23T14:18:55.401Z | Q26: ETH → SOL | R26: Layerswap | S26: =COUNTIFS($A$5:$A$214,Q26,$C$5:$C$214,R26) | T26: =COUNTIFS($A$5:$A$214,Q26,$C$5:$C$214,R26,$D$5:$D$214,">0") | U26: =IFERROR(AVERAGEIFS($D$5:$D$214,$A$5:$A$214,Q26,$C$5:$C$214,R26),"—") | V26: =IFERROR(AVERAGEIFS($H$5:$H$214,$A$5:$A$214,Q26,$C$5:$C$214,R26),"—") | W26: =IFERROR(AVERAGEIFS($I$5:$I$214,$A$5:$A$214,Q26,$C$5:$C$214,R26),"—") | X26: =IFERROR(AVERAGEIFS($K$5:$K$214,$A$5:$A$214,Q26,$C$5:$C$214,R26),"—") | Y26: 2 | Z26: =IF(T26=0,"NOT LISTED on Bridg",IF(NOT(ISNUMBER(X26)),"No direct quote",IF(ABS(X26)<=Y26,"Match (net of Bridg fee)",IF(ABS(W26)<=Y26,"Match (Bridg fee not applied)",IF(X26<0,"Bridg LOWER than venue","Bridg HIGHER than venue")))))
A27: SOL → ETH | B27: 2 | C27: Husher | D27: 99.1504 | F27: 99.05 | H27: =IF(ISNUMBER(F27),F27-N(G27),"") | I27: =IF(AND(ISNUMBER(D27),ISNUMBER(H27)),(D27-H27)/100*10000,"") | J27: 0.15 | K27: =IF(ISNUMBER(I27),I27+N(J27)/100*10000,"") | L27: 0.005 | N27: 2026-09-23T14:22:28.648Z | O27: 2026-09-23T14:22:28.643Z | Q27: ETH → SOL | R27: Meson | S27: =COUNTIFS($A$5:$A$214,Q27,$C$5:$C$214,R27) | T27: =COUNTIFS($A$5:$A$214,Q27,$C$5:$C$214,R27,$D$5:$D$214,">0") | U27: =IFERROR(AVERAGEIFS($D$5:$D$214,$A$5:$A$214,Q27,$C$5:$C$214,R27),"—") | V27: =IFERROR(AVERAGEIFS($H$5:$H$214,$A$5:$A$214,Q27,$C$5:$C$214,R27),"—") | W27: =IFERROR(AVERAGEIFS($I$5:$I$214,$A$5:$A$214,Q27,$C$5:$C$214,R27),"—") | X27: =IFERROR(AVERAGEIFS($K$5:$K$214,$A$5:$A$214,Q27,$C$5:$C$214,R27),"—") | Y27: 2 | Z27: =IF(T27=0,"NOT LISTED on Bridg",IF(NOT(ISNUMBER(X27)),"No direct quote",IF(ABS(X27)<=Y27,"Match (net of Bridg fee)",IF(ABS(W27)<=Y27,"Match (Bridg fee not applied)",IF(X27<0,"Bridg LOWER than venue","Bridg HIGHER than venue")))))
A28: SOL → ETH | B28: 3 | C28: Husher | D28: 99.1504 | F28: 99.05 | H28: =IF(ISNUMBER(F28),F28-N(G28),"") | I28: =IF(AND(ISNUMBER(D28),ISNUMBER(H28)),(D28-H28)/100*10000,"") | J28: 0.15 | K28: =IF(ISNUMBER(I28),I28+N(J28)/100*10000,"") | L28: 0.002 | N28: 2026-09-23T14:26:54.591Z | O28: 2026-09-23T14:26:54.589Z | Q28: ETH → SOL | R28: SimpleSwap | S28: =COUNTIFS($A$5:$A$214,Q28,$C$5:$C$214,R28) | T28: =COUNTIFS($A$5:$A$214,Q28,$C$5:$C$214,R28,$D$5:$D$214,">0") | U28: =IFERROR(AVERAGEIFS($D$5:$D$214,$A$5:$A$214,Q28,$C$5:$C$214,R28),"—") | V28: =IFERROR(AVERAGEIFS($H$5:$H$214,$A$5:$A$214,Q28,$C$5:$C$214,R28),"—") | W28: =IFERROR(AVERAGEIFS($I$5:$I$214,$A$5:$A$214,Q28,$C$5:$C$214,R28),"—") | X28: =IFERROR(AVERAGEIFS($K$5:$K$214,$A$5:$A$214,Q28,$C$5:$C$214,R28),"—") | Y28: 2 | Z28: =IF(T28=0,"NOT LISTED on Bridg",IF(NOT(ISNUMBER(X28)),"No direct quote",IF(ABS(X28)<=Y28,"Match (net of Bridg fee)",IF(ABS(W28)<=Y28,"Match (Bridg fee not applied)",IF(X28<0,"Bridg LOWER than venue","Bridg HIGHER than venue")))))
A29: SOL → ETH | B29: 1 | C29: Layerswap | D29: 99.433011 | F29: 99.716863 | H29: =IF(ISNUMBER(F29),F29-N(G29),"") | I29: =IF(AND(ISNUMBER(D29),ISNUMBER(H29)),(D29-H29)/100*10000,"") | J29: 0.15 | K29: =IF(ISNUMBER(I29),I29+N(J29)/100*10000,"") | L29: 0.004 | N29: 2026-09-23T14:18:55.406Z | O29: 2026-09-23T14:18:55.402Z | Q29: ETH → SOL | R29: Skip Go | S29: =COUNTIFS($A$5:$A$214,Q29,$C$5:$C$214,R29) | T29: =COUNTIFS($A$5:$A$214,Q29,$C$5:$C$214,R29,$D$5:$D$214,">0") | U29: =IFERROR(AVERAGEIFS($D$5:$D$214,$A$5:$A$214,Q29,$C$5:$C$214,R29),"—") | V29: =IFERROR(AVERAGEIFS($H$5:$H$214,$A$5:$A$214,Q29,$C$5:$C$214,R29),"—") | W29: =IFERROR(AVERAGEIFS($I$5:$I$214,$A$5:$A$214,Q29,$C$5:$C$214,R29),"—") | X29: =IFERROR(AVERAGEIFS($K$5:$K$214,$A$5:$A$214,Q29,$C$5:$C$214,R29),"—") | Y29: 2 | Z29: =IF(T29=0,"NOT LISTED on Bridg",IF(NOT(ISNUMBER(X29)),"No direct quote",IF(ABS(X29)<=Y29,"Match (net of Bridg fee)",IF(ABS(W29)<=Y29,"Match (Bridg fee not applied)",IF(X29<0,"Bridg LOWER than venue","Bridg HIGHER than venue")))))
A30: SOL → ETH | B30: 2 | C30: Layerswap | D30: 99.4339 | F30: 99.717755 | H30: =IF(ISNUMBER(F30),F30-N(G30),"") | I30: =IF(AND(ISNUMBER(D30),ISNUMBER(H30)),(D30-H30)/100*10000,"") | J30: 0.15 | K30: =IF(ISNUMBER(I30),I30+N(J30)/100*10000,"") | L30: 0.002 | N30: 2026-09-23T14:22:28.648Z | O30: 2026-09-23T14:22:28.646Z | Q30: ETH → SOL | R30: Symbiosis | S30: =COUNTIFS($A$5:$A$214,Q30,$C$5:$C$214,R30) | T30: =COUNTIFS($A$5:$A$214,Q30,$C$5:$C$214,R30,$D$5:$D$214,">0") | U30: =IFERROR(AVERAGEIFS($D$5:$D$214,$A$5:$A$214,Q30,$C$5:$C$214,R30),"—") | V30: =IFERROR(AVERAGEIFS($H$5:$H$214,$A$5:$A$214,Q30,$C$5:$C$214,R30),"—") | W30: =IFERROR(AVERAGEIFS($I$5:$I$214,$A$5:$A$214,Q30,$C$5:$C$214,R30),"—") | X30: =IFERROR(AVERAGEIFS($K$5:$K$214,$A$5:$A$214,Q30,$C$5:$C$214,R30),"—") | Y30: 2 | Z30: =IF(T30=0,"NOT LISTED on Bridg",IF(NOT(ISNUMBER(X30)),"No direct quote",IF(ABS(X30)<=Y30,"Match (net of Bridg fee)",IF(ABS(W30)<=Y30,"Match (Bridg fee not applied)",IF(X30<0,"Bridg LOWER than venue","Bridg HIGHER than venue")))))
A31: SOL → ETH | B31: 3 | C31: Layerswap | D31: 99.42273 | F31: 99.706546 | H31: =IF(ISNUMBER(F31),F31-N(G31),"") | I31: =IF(AND(ISNUMBER(D31),ISNUMBER(H31)),(D31-H31)/100*10000,"") | J31: 0.15 | K31: =IF(ISNUMBER(I31),I31+N(J31)/100*10000,"") | L31: 0.001 | N31: 2026-09-23T14:26:54.591Z | O31: 2026-09-23T14:26:54.592Z | Q31: SOL → BSC | R31: Relay | S31: =COUNTIFS($A$5:$A$214,Q31,$C$5:$C$214,R31) | T31: =COUNTIFS($A$5:$A$214,Q31,$C$5:$C$214,R31,$D$5:$D$214,">0") | U31: =IFERROR(AVERAGEIFS($D$5:$D$214,$A$5:$A$214,Q31,$C$5:$C$214,R31),"—") | V31: =IFERROR(AVERAGEIFS($H$5:$H$214,$A$5:$A$214,Q31,$C$5:$C$214,R31),"—") | W31: =IFERROR(AVERAGEIFS($I$5:$I$214,$A$5:$A$214,Q31,$C$5:$C$214,R31),"—") | X31: =IFERROR(AVERAGEIFS($K$5:$K$214,$A$5:$A$214,Q31,$C$5:$C$214,R31),"—") | Y31: 2 | Z31: =IF(T31=0,"NOT LISTED on Bridg",IF(NOT(ISNUMBER(X31)),"No direct quote",IF(ABS(X31)<=Y31,"Match (net of Bridg fee)",IF(ABS(W31)<=Y31,"Match (Bridg fee not applied)",IF(X31<0,"Bridg LOWER than venue","Bridg HIGHER than venue")))))
A32: SOL → ETH | B32: 1 | C32: Meson | D32: 99.75015 | E32: yes | F32: 98.65 | H32: =IF(ISNUMBER(F32),F32-N(G32),"") | I32: =IF(AND(ISNUMBER(D32),ISNUMBER(H32)),(D32-H32)/100*10000,"") | J32: 0.15 | K32: =IF(ISNUMBER(I32),I32+N(J32)/100*10000,"") | L32: 0.006 | N32: 2026-09-23T14:18:55.406Z | O32: 2026-09-23T14:18:55.400Z | Q32: SOL → BSC | R32: deBridge | S32: =COUNTIFS($A$5:$A$214,Q32,$C$5:$C$214,R32) | T32: =COUNTIFS($A$5:$A$214,Q32,$C$5:$C$214,R32,$D$5:$D$214,">0") | U32: =IFERROR(AVERAGEIFS($D$5:$D$214,$A$5:$A$214,Q32,$C$5:$C$214,R32),"—") | V32: =IFERROR(AVERAGEIFS($H$5:$H$214,$A$5:$A$214,Q32,$C$5:$C$214,R32),"—") | W32: =IFERROR(AVERAGEIFS($I$5:$I$214,$A$5:$A$214,Q32,$C$5:$C$214,R32),"—") | X32: =IFERROR(AVERAGEIFS($K$5:$K$214,$A$5:$A$214,Q32,$C$5:$C$214,R32),"—") | Y32: 2 | Z32: =IF(T32=0,"NOT LISTED on Bridg",IF(NOT(ISNUMBER(X32)),"No direct quote",IF(ABS(X32)<=Y32,"Match (net of Bridg fee)",IF(ABS(W32)<=Y32,"Match (Bridg fee not applied)",IF(X32<0,"Bridg LOWER than venue","Bridg HIGHER than venue")))))
